ERROR 2024-08-22 14:32:59,191 auth_views 29160 138188926682880 Login error for user kavitha.ramamoorthy@tsvglobal.com: Login failed: Email not confirmed
ERROR 2024-08-22 14:33:05,617 auth_views 29160 138188918290176 Login error for user kavitha.ramamoorthy@tsvglobal.com: Login failed: Email not confirmed
ERROR 2024-08-22 14:44:20,129 user_views 32774 137091811575552 Error during User creation: Error creating user: User not allowed
ERROR 2024-08-22 15:46:20,519 log 56413 135435820988160 Internal Server Error: /
Traceback (most recent call last):
  File "/usr/local/python/3.10.13/lib/python3.10/site-packages/django/core/handlers/exception.py", line 55, in inner
    response = get_response(request)
  File "/usr/local/python/3.10.13/lib/python3.10/site-packages/django/core/handlers/base.py", line 197, in _get_response
    response = wrapped_callback(request, *callback_args, **callback_kwargs)
  File "/workspaces/HRMS/hrms_project/hrms_project/urls.py", line 8, in <lambda>
    path('', lambda request: redirect('login')),  # Redirect root URL to the login page
  File "/usr/local/python/3.10.13/lib/python3.10/site-packages/django/shortcuts.py", line 49, in redirect
    return redirect_class(resolve_url(to, *args, **kwargs))
  File "/usr/local/python/3.10.13/lib/python3.10/site-packages/django/shortcuts.py", line 180, in resolve_url
    return reverse(to, args=args, kwargs=kwargs)
  File "/usr/local/python/3.10.13/lib/python3.10/site-packages/django/urls/base.py", line 88, in reverse
    return resolver._reverse_with_prefix(view, prefix, *args, **kwargs)
  File "/usr/local/python/3.10.13/lib/python3.10/site-packages/django/urls/resolvers.py", line 831, in _reverse_with_prefix
    raise NoReverseMatch(msg)
django.urls.exceptions.NoReverseMatch: Reverse for 'login' not found. 'login' is not a valid view function or pattern name.
ERROR 2024-08-22 15:46:20,520 basehttp 56413 135435820988160 "GET / HTTP/1.1" 500 95379
ERROR 2024-08-23 09:13:43,506 log 3660 138268295575296 Internal Server Error: /
Traceback (most recent call last):
  File "/usr/local/python/3.10.13/lib/python3.10/site-packages/django/core/handlers/exception.py", line 55, in inner
    response = get_response(request)
  File "/usr/local/python/3.10.13/lib/python3.10/site-packages/django/core/handlers/base.py", line 197, in _get_response
    response = wrapped_callback(request, *callback_args, **callback_kwargs)
  File "/workspaces/HRMS/hrms_project/hrms_project/urls.py", line 8, in <lambda>
    path('', lambda request: redirect('login')),  # Redirect root URL to the login page
  File "/usr/local/python/3.10.13/lib/python3.10/site-packages/django/shortcuts.py", line 49, in redirect
    return redirect_class(resolve_url(to, *args, **kwargs))
  File "/usr/local/python/3.10.13/lib/python3.10/site-packages/django/shortcuts.py", line 180, in resolve_url
    return reverse(to, args=args, kwargs=kwargs)
  File "/usr/local/python/3.10.13/lib/python3.10/site-packages/django/urls/base.py", line 88, in reverse
    return resolver._reverse_with_prefix(view, prefix, *args, **kwargs)
  File "/usr/local/python/3.10.13/lib/python3.10/site-packages/django/urls/resolvers.py", line 831, in _reverse_with_prefix
    raise NoReverseMatch(msg)
django.urls.exceptions.NoReverseMatch: Reverse for 'login' not found. 'login' is not a valid view function or pattern name.
ERROR 2024-08-23 09:13:43,510 basehttp 3660 138268295575296 "GET / HTTP/1.1" 500 95387
ERROR 2024-08-23 09:22:30,663 log 7428 127216461543168 Internal Server Error: /login/
Traceback (most recent call last):
  File "/usr/local/python/3.10.13/lib/python3.10/site-packages/django/core/handlers/exception.py", line 55, in inner
    response = get_response(request)
  File "/usr/local/python/3.10.13/lib/python3.10/site-packages/django/core/handlers/base.py", line 197, in _get_response
    response = wrapped_callback(request, *callback_args, **callback_kwargs)
  File "/workspaces/HRMS/hrms_project/accounts/views/auth_views.py", line 29, in login_view
    return redirect('home')
  File "/usr/local/python/3.10.13/lib/python3.10/site-packages/django/shortcuts.py", line 49, in redirect
    return redirect_class(resolve_url(to, *args, **kwargs))
  File "/usr/local/python/3.10.13/lib/python3.10/site-packages/django/shortcuts.py", line 180, in resolve_url
    return reverse(to, args=args, kwargs=kwargs)
  File "/usr/local/python/3.10.13/lib/python3.10/site-packages/django/urls/base.py", line 88, in reverse
    return resolver._reverse_with_prefix(view, prefix, *args, **kwargs)
  File "/usr/local/python/3.10.13/lib/python3.10/site-packages/django/urls/resolvers.py", line 831, in _reverse_with_prefix
    raise NoReverseMatch(msg)
django.urls.exceptions.NoReverseMatch: Reverse for 'home' not found. 'home' is not a valid view function or pattern name.
ERROR 2024-08-23 09:22:30,665 basehttp 7428 127216461543168 "POST /login/ HTTP/1.1" 500 100043
ERROR 2024-08-23 09:27:31,623 log 9747 135314219726592 Internal Server Error: /accounts/auth/login/
Traceback (most recent call last):
  File "/usr/local/python/3.10.13/lib/python3.10/site-packages/django/core/handlers/exception.py", line 55, in inner
    response = get_response(request)
  File "/usr/local/python/3.10.13/lib/python3.10/site-packages/django/core/handlers/base.py", line 197, in _get_response
    response = wrapped_callback(request, *callback_args, **callback_kwargs)
  File "/workspaces/HRMS/hrms_project/accounts/views/auth_views.py", line 29, in login_view
    return redirect('home')
  File "/usr/local/python/3.10.13/lib/python3.10/site-packages/django/shortcuts.py", line 49, in redirect
    return redirect_class(resolve_url(to, *args, **kwargs))
  File "/usr/local/python/3.10.13/lib/python3.10/site-packages/django/shortcuts.py", line 180, in resolve_url
    return reverse(to, args=args, kwargs=kwargs)
  File "/usr/local/python/3.10.13/lib/python3.10/site-packages/django/urls/base.py", line 88, in reverse
    return resolver._reverse_with_prefix(view, prefix, *args, **kwargs)
  File "/usr/local/python/3.10.13/lib/python3.10/site-packages/django/urls/resolvers.py", line 831, in _reverse_with_prefix
    raise NoReverseMatch(msg)
django.urls.exceptions.NoReverseMatch: Reverse for 'home' not found. 'home' is not a valid view function or pattern name.
ERROR 2024-08-23 09:27:31,625 basehttp 9747 135314219726592 "POST /accounts/auth/login/ HTTP/1.1" 500 100209
ERROR 2024-08-23 09:28:06,623 log 10034 130819224590080 Internal Server Error: /accounts/dashboard/
Traceback (most recent call last):
  File "/usr/local/python/3.10.13/lib/python3.10/site-packages/django/core/handlers/exception.py", line 55, in inner
    response = get_response(request)
  File "/usr/local/python/3.10.13/lib/python3.10/site-packages/django/core/handlers/base.py", line 197, in _get_response
    response = wrapped_callback(request, *callback_args, **callback_kwargs)
  File "/usr/local/python/3.10.13/lib/python3.10/site-packages/django/contrib/auth/decorators.py", line 60, in _view_wrapper
    return view_func(request, *args, **kwargs)
  File "/workspaces/HRMS/hrms_project/accounts/views/dashboard_views.py", line 11, in home_view
    return redirect('admin_dashboard')
  File "/usr/local/python/3.10.13/lib/python3.10/site-packages/django/shortcuts.py", line 49, in redirect
    return redirect_class(resolve_url(to, *args, **kwargs))
  File "/usr/local/python/3.10.13/lib/python3.10/site-packages/django/shortcuts.py", line 180, in resolve_url
    return reverse(to, args=args, kwargs=kwargs)
  File "/usr/local/python/3.10.13/lib/python3.10/site-packages/django/urls/base.py", line 88, in reverse
    return resolver._reverse_with_prefix(view, prefix, *args, **kwargs)
  File "/usr/local/python/3.10.13/lib/python3.10/site-packages/django/urls/resolvers.py", line 831, in _reverse_with_prefix
    raise NoReverseMatch(msg)
django.urls.exceptions.NoReverseMatch: Reverse for 'admin_dashboard' not found. 'admin_dashboard' is not a valid view function or pattern name.
ERROR 2024-08-23 09:28:06,625 basehttp 10034 130819224590080 "GET /accounts/dashboard/ HTTP/1.1" 500 103598
ERROR 2024-08-23 09:28:44,770 log 10359 135045608093440 Internal Server Error: /accounts/dashboard/
Traceback (most recent call last):
  File "/usr/local/python/3.10.13/lib/python3.10/site-packages/django/urls/base.py", line 71, in reverse
    extra, resolver = resolver.namespace_dict[ns]
KeyError: 'account'

During handling of the above exception, another exception occurred:

Traceback (most recent call last):
  File "/usr/local/python/3.10.13/lib/python3.10/site-packages/django/core/handlers/exception.py", line 55, in inner
    response = get_response(request)
  File "/usr/local/python/3.10.13/lib/python3.10/site-packages/django/core/handlers/base.py", line 197, in _get_response
    response = wrapped_callback(request, *callback_args, **callback_kwargs)
  File "/usr/local/python/3.10.13/lib/python3.10/site-packages/django/contrib/auth/decorators.py", line 60, in _view_wrapper
    return view_func(request, *args, **kwargs)
  File "/workspaces/HRMS/hrms_project/accounts/views/dashboard_views.py", line 11, in home_view
    return redirect('account:admin_dashboard')
  File "/usr/local/python/3.10.13/lib/python3.10/site-packages/django/shortcuts.py", line 49, in redirect
    return redirect_class(resolve_url(to, *args, **kwargs))
  File "/usr/local/python/3.10.13/lib/python3.10/site-packages/django/shortcuts.py", line 180, in resolve_url
    return reverse(to, args=args, kwargs=kwargs)
  File "/usr/local/python/3.10.13/lib/python3.10/site-packages/django/urls/base.py", line 82, in reverse
    raise NoReverseMatch("%s is not a registered namespace" % key)
django.urls.exceptions.NoReverseMatch: 'account' is not a registered namespace
ERROR 2024-08-23 09:28:44,771 basehttp 10359 135045608093440 "GET /accounts/dashboard/ HTTP/1.1" 500 105709
ERROR 2024-08-23 09:54:38,290 log 19946 128384810080000 Internal Server Error: /accounts/users/create/
Traceback (most recent call last):
  File "/usr/local/python/3.10.13/lib/python3.10/site-packages/django/core/handlers/exception.py", line 55, in inner
    response = get_response(request)
  File "/usr/local/python/3.10.13/lib/python3.10/site-packages/django/core/handlers/base.py", line 197, in _get_response
    response = wrapped_callback(request, *callback_args, **callback_kwargs)
  File "/usr/local/python/3.10.13/lib/python3.10/site-packages/django/contrib/auth/decorators.py", line 60, in _view_wrapper
    return view_func(request, *args, **kwargs)
  File "/workspaces/HRMS/hrms_project/accounts/utils/decorators.py", line 22, in wrapper
    return redirect('home')
  File "/usr/local/python/3.10.13/lib/python3.10/site-packages/django/shortcuts.py", line 49, in redirect
    return redirect_class(resolve_url(to, *args, **kwargs))
  File "/usr/local/python/3.10.13/lib/python3.10/site-packages/django/shortcuts.py", line 180, in resolve_url
    return reverse(to, args=args, kwargs=kwargs)
  File "/usr/local/python/3.10.13/lib/python3.10/site-packages/django/urls/base.py", line 88, in reverse
    return resolver._reverse_with_prefix(view, prefix, *args, **kwargs)
  File "/usr/local/python/3.10.13/lib/python3.10/site-packages/django/urls/resolvers.py", line 831, in _reverse_with_prefix
    raise NoReverseMatch(msg)
django.urls.exceptions.NoReverseMatch: Reverse for 'home' not found. 'home' is not a valid view function or pattern name.
ERROR 2024-08-23 09:54:38,291 basehttp 19946 128384810080000 "GET /accounts/users/create/ HTTP/1.1" 500 103195
ERROR 2024-08-23 10:17:06,647 log 28094 125109956232960 Internal Server Error: /accounts/employees/add/
Traceback (most recent call last):
  File "/usr/local/python/3.10.13/lib/python3.10/site-packages/django/template/backends/django.py", line 107, in render
    return self.template.render(context)
  File "/usr/local/python/3.10.13/lib/python3.10/site-packages/django/template/base.py", line 171, in render
    return self._render(context)
  File "/usr/local/python/3.10.13/lib/python3.10/site-packages/django/template/base.py", line 163, in _render
    return self.nodelist.render(context)
  File "/usr/local/python/3.10.13/lib/python3.10/site-packages/django/template/base.py", line 1008, in render
    return SafeString("".join([node.render_annotated(context) for node in self]))
  File "/usr/local/python/3.10.13/lib/python3.10/site-packages/django/template/base.py", line 1008, in <listcomp>
    return SafeString("".join([node.render_annotated(context) for node in self]))
  File "/usr/local/python/3.10.13/lib/python3.10/site-packages/django/template/base.py", line 969, in render_annotated
    return self.render(context)
  File "/usr/local/python/3.10.13/lib/python3.10/site-packages/django/template/loader_tags.py", line 134, in render
    compiled_parent = self.get_parent(context)
  File "/usr/local/python/3.10.13/lib/python3.10/site-packages/django/template/loader_tags.py", line 131, in get_parent
    return self.find_template(parent, context)
  File "/usr/local/python/3.10.13/lib/python3.10/site-packages/django/template/loader_tags.py", line 109, in find_template
    template, origin = context.template.engine.find_template(
  File "/usr/local/python/3.10.13/lib/python3.10/site-packages/django/template/engine.py", line 163, in find_template
    raise TemplateDoesNotExist(name, tried=tried)
django.template.exceptions.TemplateDoesNotExist: base.html

The above exception was the direct cause of the following exception:

Traceback (most recent call last):
  File "/usr/local/python/3.10.13/lib/python3.10/site-packages/django/core/handlers/exception.py", line 55, in inner
    response = get_response(request)
  File "/usr/local/python/3.10.13/lib/python3.10/site-packages/django/core/handlers/base.py", line 197, in _get_response
    response = wrapped_callback(request, *callback_args, **callback_kwargs)
  File "/usr/local/python/3.10.13/lib/python3.10/site-packages/django/contrib/auth/decorators.py", line 60, in _view_wrapper
    return view_func(request, *args, **kwargs)
  File "/workspaces/HRMS/hrms_project/accounts/views/employee_views.py", line 6, in add_employee
    return render(request, 'accounts/add_employee.html')
  File "/usr/local/python/3.10.13/lib/python3.10/site-packages/django/shortcuts.py", line 25, in render
    content = loader.render_to_string(template_name, context, request, using=using)
  File "/usr/local/python/3.10.13/lib/python3.10/site-packages/django/template/loader.py", line 62, in render_to_string
    return template.render(context, request)
  File "/usr/local/python/3.10.13/lib/python3.10/site-packages/django/template/backends/django.py", line 109, in render
    reraise(exc, self.backend)
  File "/usr/local/python/3.10.13/lib/python3.10/site-packages/django/template/backends/django.py", line 130, in reraise
    raise new from exc
django.template.exceptions.TemplateDoesNotExist: base.html
ERROR 2024-08-23 10:17:06,649 basehttp 28094 125109956232960 "GET /accounts/employees/add/ HTTP/1.1" 500 145664
ERROR 2024-08-23 10:17:14,630 log 28094 125110061594368 Internal Server Error: /accounts/employees/add/
Traceback (most recent call last):
  File "/usr/local/python/3.10.13/lib/python3.10/site-packages/django/template/backends/django.py", line 107, in render
    return self.template.render(context)
  File "/usr/local/python/3.10.13/lib/python3.10/site-packages/django/template/base.py", line 171, in render
    return self._render(context)
  File "/usr/local/python/3.10.13/lib/python3.10/site-packages/django/template/base.py", line 163, in _render
    return self.nodelist.render(context)
  File "/usr/local/python/3.10.13/lib/python3.10/site-packages/django/template/base.py", line 1008, in render
    return SafeString("".join([node.render_annotated(context) for node in self]))
  File "/usr/local/python/3.10.13/lib/python3.10/site-packages/django/template/base.py", line 1008, in <listcomp>
    return SafeString("".join([node.render_annotated(context) for node in self]))
  File "/usr/local/python/3.10.13/lib/python3.10/site-packages/django/template/base.py", line 969, in render_annotated
    return self.render(context)
  File "/usr/local/python/3.10.13/lib/python3.10/site-packages/django/template/loader_tags.py", line 134, in render
    compiled_parent = self.get_parent(context)
  File "/usr/local/python/3.10.13/lib/python3.10/site-packages/django/template/loader_tags.py", line 131, in get_parent
    return self.find_template(parent, context)
  File "/usr/local/python/3.10.13/lib/python3.10/site-packages/django/template/loader_tags.py", line 109, in find_template
    template, origin = context.template.engine.find_template(
  File "/usr/local/python/3.10.13/lib/python3.10/site-packages/django/template/engine.py", line 163, in find_template
    raise TemplateDoesNotExist(name, tried=tried)
django.template.exceptions.TemplateDoesNotExist: base.html

The above exception was the direct cause of the following exception:

Traceback (most recent call last):
  File "/usr/local/python/3.10.13/lib/python3.10/site-packages/django/core/handlers/exception.py", line 55, in inner
    response = get_response(request)
  File "/usr/local/python/3.10.13/lib/python3.10/site-packages/django/core/handlers/base.py", line 197, in _get_response
    response = wrapped_callback(request, *callback_args, **callback_kwargs)
  File "/usr/local/python/3.10.13/lib/python3.10/site-packages/django/contrib/auth/decorators.py", line 60, in _view_wrapper
    return view_func(request, *args, **kwargs)
  File "/workspaces/HRMS/hrms_project/accounts/views/employee_views.py", line 6, in add_employee
    return render(request, 'accounts/add_employee.html')
  File "/usr/local/python/3.10.13/lib/python3.10/site-packages/django/shortcuts.py", line 25, in render
    content = loader.render_to_string(template_name, context, request, using=using)
  File "/usr/local/python/3.10.13/lib/python3.10/site-packages/django/template/loader.py", line 62, in render_to_string
    return template.render(context, request)
  File "/usr/local/python/3.10.13/lib/python3.10/site-packages/django/template/backends/django.py", line 109, in render
    reraise(exc, self.backend)
  File "/usr/local/python/3.10.13/lib/python3.10/site-packages/django/template/backends/django.py", line 130, in reraise
    raise new from exc
django.template.exceptions.TemplateDoesNotExist: base.html
ERROR 2024-08-23 10:17:14,631 basehttp 28094 125110061594368 "GET /accounts/employees/add/ HTTP/1.1" 500 145664
ERROR 2024-08-23 10:20:30,097 log 29562 126197166663424 Internal Server Error: /accounts/employees/list/
Traceback (most recent call last):
  File "/usr/local/python/3.10.13/lib/python3.10/site-packages/django/core/handlers/exception.py", line 55, in inner
    response = get_response(request)
  File "/usr/local/python/3.10.13/lib/python3.10/site-packages/django/core/handlers/base.py", line 197, in _get_response
    response = wrapped_callback(request, *callback_args, **callback_kwargs)
  File "/usr/local/python/3.10.13/lib/python3.10/site-packages/django/contrib/auth/decorators.py", line 60, in _view_wrapper
    return view_func(request, *args, **kwargs)
  File "/workspaces/HRMS/hrms_project/accounts/views/employee_views.py", line 11, in list_employees
    return render(request, 'accounts/list_employees.html', {'employees': employees})
  File "/usr/local/python/3.10.13/lib/python3.10/site-packages/django/shortcuts.py", line 25, in render
    content = loader.render_to_string(template_name, context, request, using=using)
  File "/usr/local/python/3.10.13/lib/python3.10/site-packages/django/template/loader.py", line 61, in render_to_string
    template = get_template(template_name, using=using)
  File "/usr/local/python/3.10.13/lib/python3.10/site-packages/django/template/loader.py", line 19, in get_template
    raise TemplateDoesNotExist(template_name, chain=chain)
django.template.exceptions.TemplateDoesNotExist: accounts/list_employees.html
ERROR 2024-08-23 10:20:30,099 basehttp 29562 126197166663424 "GET /accounts/employees/list/ HTTP/1.1" 500 96811
ERROR 2024-08-23 10:20:45,552 log 29562 126196926895872 Internal Server Error: /accounts/leaves/approve/
Traceback (most recent call last):
  File "/usr/local/python/3.10.13/lib/python3.10/site-packages/django/template/backends/django.py", line 107, in render
    return self.template.render(context)
  File "/usr/local/python/3.10.13/lib/python3.10/site-packages/django/template/base.py", line 171, in render
    return self._render(context)
  File "/usr/local/python/3.10.13/lib/python3.10/site-packages/django/template/base.py", line 163, in _render
    return self.nodelist.render(context)
  File "/usr/local/python/3.10.13/lib/python3.10/site-packages/django/template/base.py", line 1008, in render
    return SafeString("".join([node.render_annotated(context) for node in self]))
  File "/usr/local/python/3.10.13/lib/python3.10/site-packages/django/template/base.py", line 1008, in <listcomp>
    return SafeString("".join([node.render_annotated(context) for node in self]))
  File "/usr/local/python/3.10.13/lib/python3.10/site-packages/django/template/base.py", line 969, in render_annotated
    return self.render(context)
  File "/usr/local/python/3.10.13/lib/python3.10/site-packages/django/template/loader_tags.py", line 134, in render
    compiled_parent = self.get_parent(context)
  File "/usr/local/python/3.10.13/lib/python3.10/site-packages/django/template/loader_tags.py", line 131, in get_parent
    return self.find_template(parent, context)
  File "/usr/local/python/3.10.13/lib/python3.10/site-packages/django/template/loader_tags.py", line 109, in find_template
    template, origin = context.template.engine.find_template(
  File "/usr/local/python/3.10.13/lib/python3.10/site-packages/django/template/engine.py", line 163, in find_template
    raise TemplateDoesNotExist(name, tried=tried)
django.template.exceptions.TemplateDoesNotExist: base.html

The above exception was the direct cause of the following exception:

Traceback (most recent call last):
  File "/usr/local/python/3.10.13/lib/python3.10/site-packages/django/core/handlers/exception.py", line 55, in inner
    response = get_response(request)
  File "/usr/local/python/3.10.13/lib/python3.10/site-packages/django/core/handlers/base.py", line 197, in _get_response
    response = wrapped_callback(request, *callback_args, **callback_kwargs)
  File "/usr/local/python/3.10.13/lib/python3.10/site-packages/django/contrib/auth/decorators.py", line 60, in _view_wrapper
    return view_func(request, *args, **kwargs)
  File "/workspaces/HRMS/hrms_project/accounts/views/leave_views.py", line 7, in approve_leaves
    return render(request, 'accounts/approve_leaves.html', {'leave_requests': leave_requests})
  File "/usr/local/python/3.10.13/lib/python3.10/site-packages/django/shortcuts.py", line 25, in render
    content = loader.render_to_string(template_name, context, request, using=using)
  File "/usr/local/python/3.10.13/lib/python3.10/site-packages/django/template/loader.py", line 62, in render_to_string
    return template.render(context, request)
  File "/usr/local/python/3.10.13/lib/python3.10/site-packages/django/template/backends/django.py", line 109, in render
    reraise(exc, self.backend)
  File "/usr/local/python/3.10.13/lib/python3.10/site-packages/django/template/backends/django.py", line 130, in reraise
    raise new from exc
django.template.exceptions.TemplateDoesNotExist: base.html
ERROR 2024-08-23 10:20:45,553 basehttp 29562 126196926895872 "GET /accounts/leaves/approve/ HTTP/1.1" 500 147740
ERROR 2024-08-23 10:20:48,690 log 29562 126196918503168 Internal Server Error: /accounts/leaves/reports/
Traceback (most recent call last):
  File "/usr/local/python/3.10.13/lib/python3.10/site-packages/django/template/backends/django.py", line 107, in render
    return self.template.render(context)
  File "/usr/local/python/3.10.13/lib/python3.10/site-packages/django/template/base.py", line 171, in render
    return self._render(context)
  File "/usr/local/python/3.10.13/lib/python3.10/site-packages/django/template/base.py", line 163, in _render
    return self.nodelist.render(context)
  File "/usr/local/python/3.10.13/lib/python3.10/site-packages/django/template/base.py", line 1008, in render
    return SafeString("".join([node.render_annotated(context) for node in self]))
  File "/usr/local/python/3.10.13/lib/python3.10/site-packages/django/template/base.py", line 1008, in <listcomp>
    return SafeString("".join([node.render_annotated(context) for node in self]))
  File "/usr/local/python/3.10.13/lib/python3.10/site-packages/django/template/base.py", line 969, in render_annotated
    return self.render(context)
  File "/usr/local/python/3.10.13/lib/python3.10/site-packages/django/template/loader_tags.py", line 134, in render
    compiled_parent = self.get_parent(context)
  File "/usr/local/python/3.10.13/lib/python3.10/site-packages/django/template/loader_tags.py", line 131, in get_parent
    return self.find_template(parent, context)
  File "/usr/local/python/3.10.13/lib/python3.10/site-packages/django/template/loader_tags.py", line 109, in find_template
    template, origin = context.template.engine.find_template(
  File "/usr/local/python/3.10.13/lib/python3.10/site-packages/django/template/engine.py", line 163, in find_template
    raise TemplateDoesNotExist(name, tried=tried)
django.template.exceptions.TemplateDoesNotExist: base.html

The above exception was the direct cause of the following exception:

Traceback (most recent call last):
  File "/usr/local/python/3.10.13/lib/python3.10/site-packages/django/core/handlers/exception.py", line 55, in inner
    response = get_response(request)
  File "/usr/local/python/3.10.13/lib/python3.10/site-packages/django/core/handlers/base.py", line 197, in _get_response
    response = wrapped_callback(request, *callback_args, **callback_kwargs)
  File "/usr/local/python/3.10.13/lib/python3.10/site-packages/django/contrib/auth/decorators.py", line 60, in _view_wrapper
    return view_func(request, *args, **kwargs)
  File "/workspaces/HRMS/hrms_project/accounts/views/leave_views.py", line 12, in leave_reports
    return render(request, 'accounts/leave_reports.html', {'reports': reports})
  File "/usr/local/python/3.10.13/lib/python3.10/site-packages/django/shortcuts.py", line 25, in render
    content = loader.render_to_string(template_name, context, request, using=using)
  File "/usr/local/python/3.10.13/lib/python3.10/site-packages/django/template/loader.py", line 62, in render_to_string
    return template.render(context, request)
  File "/usr/local/python/3.10.13/lib/python3.10/site-packages/django/template/backends/django.py", line 109, in render
    reraise(exc, self.backend)
  File "/usr/local/python/3.10.13/lib/python3.10/site-packages/django/template/backends/django.py", line 130, in reraise
    raise new from exc
django.template.exceptions.TemplateDoesNotExist: base.html
ERROR 2024-08-23 10:20:48,691 basehttp 29562 126196918503168 "GET /accounts/leaves/reports/ HTTP/1.1" 500 146268
ERROR 2024-08-23 10:20:51,750 log 29562 126197166663424 Internal Server Error: /accounts/kyc/pending/
Traceback (most recent call last):
  File "/usr/local/python/3.10.13/lib/python3.10/site-packages/django/template/backends/django.py", line 107, in render
    return self.template.render(context)
  File "/usr/local/python/3.10.13/lib/python3.10/site-packages/django/template/base.py", line 171, in render
    return self._render(context)
  File "/usr/local/python/3.10.13/lib/python3.10/site-packages/django/template/base.py", line 163, in _render
    return self.nodelist.render(context)
  File "/usr/local/python/3.10.13/lib/python3.10/site-packages/django/template/base.py", line 1008, in render
    return SafeString("".join([node.render_annotated(context) for node in self]))
  File "/usr/local/python/3.10.13/lib/python3.10/site-packages/django/template/base.py", line 1008, in <listcomp>
    return SafeString("".join([node.render_annotated(context) for node in self]))
  File "/usr/local/python/3.10.13/lib/python3.10/site-packages/django/template/base.py", line 969, in render_annotated
    return self.render(context)
  File "/usr/local/python/3.10.13/lib/python3.10/site-packages/django/template/loader_tags.py", line 134, in render
    compiled_parent = self.get_parent(context)
  File "/usr/local/python/3.10.13/lib/python3.10/site-packages/django/template/loader_tags.py", line 131, in get_parent
    return self.find_template(parent, context)
  File "/usr/local/python/3.10.13/lib/python3.10/site-packages/django/template/loader_tags.py", line 109, in find_template
    template, origin = context.template.engine.find_template(
  File "/usr/local/python/3.10.13/lib/python3.10/site-packages/django/template/engine.py", line 163, in find_template
    raise TemplateDoesNotExist(name, tried=tried)
django.template.exceptions.TemplateDoesNotExist: base.html

The above exception was the direct cause of the following exception:

Traceback (most recent call last):
  File "/usr/local/python/3.10.13/lib/python3.10/site-packages/django/core/handlers/exception.py", line 55, in inner
    response = get_response(request)
  File "/usr/local/python/3.10.13/lib/python3.10/site-packages/django/core/handlers/base.py", line 197, in _get_response
    response = wrapped_callback(request, *callback_args, **callback_kwargs)
  File "/usr/local/python/3.10.13/lib/python3.10/site-packages/django/contrib/auth/decorators.py", line 60, in _view_wrapper
    return view_func(request, *args, **kwargs)
  File "/workspaces/HRMS/hrms_project/accounts/views/kyc_views.py", line 7, in pending_kyc
    return render(request, 'accounts/pending_kyc.html', {'pending_applications': pending_applications})
  File "/usr/local/python/3.10.13/lib/python3.10/site-packages/django/shortcuts.py", line 25, in render
    content = loader.render_to_string(template_name, context, request, using=using)
  File "/usr/local/python/3.10.13/lib/python3.10/site-packages/django/template/loader.py", line 62, in render_to_string
    return template.render(context, request)
  File "/usr/local/python/3.10.13/lib/python3.10/site-packages/django/template/backends/django.py", line 109, in render
    reraise(exc, self.backend)
  File "/usr/local/python/3.10.13/lib/python3.10/site-packages/django/template/backends/django.py", line 130, in reraise
    raise new from exc
django.template.exceptions.TemplateDoesNotExist: base.html
ERROR 2024-08-23 10:20:51,752 basehttp 29562 126197166663424 "GET /accounts/kyc/pending/ HTTP/1.1" 500 147213
ERROR 2024-08-23 10:20:54,343 log 29562 126197166663424 Internal Server Error: /accounts/kyc/reports/
Traceback (most recent call last):
  File "/usr/local/python/3.10.13/lib/python3.10/site-packages/django/template/backends/django.py", line 107, in render
    return self.template.render(context)
  File "/usr/local/python/3.10.13/lib/python3.10/site-packages/django/template/base.py", line 171, in render
    return self._render(context)
  File "/usr/local/python/3.10.13/lib/python3.10/site-packages/django/template/base.py", line 163, in _render
    return self.nodelist.render(context)
  File "/usr/local/python/3.10.13/lib/python3.10/site-packages/django/template/base.py", line 1008, in render
    return SafeString("".join([node.render_annotated(context) for node in self]))
  File "/usr/local/python/3.10.13/lib/python3.10/site-packages/django/template/base.py", line 1008, in <listcomp>
    return SafeString("".join([node.render_annotated(context) for node in self]))
  File "/usr/local/python/3.10.13/lib/python3.10/site-packages/django/template/base.py", line 969, in render_annotated
    return self.render(context)
  File "/usr/local/python/3.10.13/lib/python3.10/site-packages/django/template/loader_tags.py", line 134, in render
    compiled_parent = self.get_parent(context)
  File "/usr/local/python/3.10.13/lib/python3.10/site-packages/django/template/loader_tags.py", line 131, in get_parent
    return self.find_template(parent, context)
  File "/usr/local/python/3.10.13/lib/python3.10/site-packages/django/template/loader_tags.py", line 109, in find_template
    template, origin = context.template.engine.find_template(
  File "/usr/local/python/3.10.13/lib/python3.10/site-packages/django/template/engine.py", line 163, in find_template
    raise TemplateDoesNotExist(name, tried=tried)
django.template.exceptions.TemplateDoesNotExist: base.html

The above exception was the direct cause of the following exception:

Traceback (most recent call last):
  File "/usr/local/python/3.10.13/lib/python3.10/site-packages/django/core/handlers/exception.py", line 55, in inner
    response = get_response(request)
  File "/usr/local/python/3.10.13/lib/python3.10/site-packages/django/core/handlers/base.py", line 197, in _get_response
    response = wrapped_callback(request, *callback_args, **callback_kwargs)
  File "/usr/local/python/3.10.13/lib/python3.10/site-packages/django/contrib/auth/decorators.py", line 60, in _view_wrapper
    return view_func(request, *args, **kwargs)
  File "/workspaces/HRMS/hrms_project/accounts/views/kyc_views.py", line 12, in kyc_reports
    return render(request, 'accounts/kyc_reports.html', {'kyc_report_data': kyc_report_data})
  File "/usr/local/python/3.10.13/lib/python3.10/site-packages/django/shortcuts.py", line 25, in render
    content = loader.render_to_string(template_name, context, request, using=using)
  File "/usr/local/python/3.10.13/lib/python3.10/site-packages/django/template/loader.py", line 62, in render_to_string
    return template.render(context, request)
  File "/usr/local/python/3.10.13/lib/python3.10/site-packages/django/template/backends/django.py", line 109, in render
    reraise(exc, self.backend)
  File "/usr/local/python/3.10.13/lib/python3.10/site-packages/django/template/backends/django.py", line 130, in reraise
    raise new from exc
django.template.exceptions.TemplateDoesNotExist: base.html
ERROR 2024-08-23 10:20:54,345 basehttp 29562 126197166663424 "GET /accounts/kyc/reports/ HTTP/1.1" 500 146333
ERROR 2024-08-23 10:22:06,741 log 29562 126196926895872 Internal Server Error: /accounts/kyc/reports/
Traceback (most recent call last):
  File "/usr/local/python/3.10.13/lib/python3.10/site-packages/django/template/backends/django.py", line 107, in render
    return self.template.render(context)
  File "/usr/local/python/3.10.13/lib/python3.10/site-packages/django/template/base.py", line 171, in render
    return self._render(context)
  File "/usr/local/python/3.10.13/lib/python3.10/site-packages/django/template/base.py", line 163, in _render
    return self.nodelist.render(context)
  File "/usr/local/python/3.10.13/lib/python3.10/site-packages/django/template/base.py", line 1008, in render
    return SafeString("".join([node.render_annotated(context) for node in self]))
  File "/usr/local/python/3.10.13/lib/python3.10/site-packages/django/template/base.py", line 1008, in <listcomp>
    return SafeString("".join([node.render_annotated(context) for node in self]))
  File "/usr/local/python/3.10.13/lib/python3.10/site-packages/django/template/base.py", line 969, in render_annotated
    return self.render(context)
  File "/usr/local/python/3.10.13/lib/python3.10/site-packages/django/template/loader_tags.py", line 134, in render
    compiled_parent = self.get_parent(context)
  File "/usr/local/python/3.10.13/lib/python3.10/site-packages/django/template/loader_tags.py", line 131, in get_parent
    return self.find_template(parent, context)
  File "/usr/local/python/3.10.13/lib/python3.10/site-packages/django/template/loader_tags.py", line 109, in find_template
    template, origin = context.template.engine.find_template(
  File "/usr/local/python/3.10.13/lib/python3.10/site-packages/django/template/engine.py", line 163, in find_template
    raise TemplateDoesNotExist(name, tried=tried)
django.template.exceptions.TemplateDoesNotExist: base.html

The above exception was the direct cause of the following exception:

Traceback (most recent call last):
  File "/usr/local/python/3.10.13/lib/python3.10/site-packages/django/core/handlers/exception.py", line 55, in inner
    response = get_response(request)
  File "/usr/local/python/3.10.13/lib/python3.10/site-packages/django/core/handlers/base.py", line 197, in _get_response
    response = wrapped_callback(request, *callback_args, **callback_kwargs)
  File "/usr/local/python/3.10.13/lib/python3.10/site-packages/django/contrib/auth/decorators.py", line 60, in _view_wrapper
    return view_func(request, *args, **kwargs)
  File "/workspaces/HRMS/hrms_project/accounts/views/kyc_views.py", line 12, in kyc_reports
    return render(request, 'accounts/kyc_reports.html', {'kyc_report_data': kyc_report_data})
  File "/usr/local/python/3.10.13/lib/python3.10/site-packages/django/shortcuts.py", line 25, in render
    content = loader.render_to_string(template_name, context, request, using=using)
  File "/usr/local/python/3.10.13/lib/python3.10/site-packages/django/template/loader.py", line 62, in render_to_string
    return template.render(context, request)
  File "/usr/local/python/3.10.13/lib/python3.10/site-packages/django/template/backends/django.py", line 109, in render
    reraise(exc, self.backend)
  File "/usr/local/python/3.10.13/lib/python3.10/site-packages/django/template/backends/django.py", line 130, in reraise
    raise new from exc
django.template.exceptions.TemplateDoesNotExist: base.html
ERROR 2024-08-23 10:22:06,742 basehttp 29562 126196926895872 "GET /accounts/kyc/reports/ HTTP/1.1" 500 146321
ERROR 2024-08-23 12:22:55,260 log 2579 138526756001536 Internal Server Error: /accounts/login/
Traceback (most recent call last):
  File "/usr/local/python/3.10.13/lib/python3.10/site-packages/django/template/base.py", line 510, in parse
    compile_func = self.tags[command]
KeyError: 'static'

During handling of the above exception, another exception occurred:

Traceback (most recent call last):
  File "/usr/local/python/3.10.13/lib/python3.10/site-packages/django/core/handlers/exception.py", line 55, in inner
    response = get_response(request)
  File "/usr/local/python/3.10.13/lib/python3.10/site-packages/django/core/handlers/base.py", line 197, in _get_response
    response = wrapped_callback(request, *callback_args, **callback_kwargs)
  File "/workspaces/HRMS/hrms_project/accounts/views/auth_views.py", line 34, in login_view
    return render(request, 'accounts/login.html')
  File "/usr/local/python/3.10.13/lib/python3.10/site-packages/django/shortcuts.py", line 25, in render
    content = loader.render_to_string(template_name, context, request, using=using)
  File "/usr/local/python/3.10.13/lib/python3.10/site-packages/django/template/loader.py", line 61, in render_to_string
    template = get_template(template_name, using=using)
  File "/usr/local/python/3.10.13/lib/python3.10/site-packages/django/template/loader.py", line 15, in get_template
    return engine.get_template(template_name)
  File "/usr/local/python/3.10.13/lib/python3.10/site-packages/django/template/backends/django.py", line 79, in get_template
    return Template(self.engine.get_template(template_name), self)
  File "/usr/local/python/3.10.13/lib/python3.10/site-packages/django/template/engine.py", line 177, in get_template
    template, origin = self.find_template(template_name)
  File "/usr/local/python/3.10.13/lib/python3.10/site-packages/django/template/engine.py", line 159, in find_template
    template = loader.get_template(name, skip=skip)
  File "/usr/local/python/3.10.13/lib/python3.10/site-packages/django/template/loaders/cached.py", line 57, in get_template
    template = super().get_template(template_name, skip)
  File "/usr/local/python/3.10.13/lib/python3.10/site-packages/django/template/loaders/base.py", line 28, in get_template
    return Template(
  File "/usr/local/python/3.10.13/lib/python3.10/site-packages/django/template/base.py", line 154, in __init__
    self.nodelist = self.compile_nodelist()
  File "/usr/local/python/3.10.13/lib/python3.10/site-packages/django/template/base.py", line 196, in compile_nodelist
    nodelist = parser.parse()
  File "/usr/local/python/3.10.13/lib/python3.10/site-packages/django/template/base.py", line 512, in parse
    self.invalid_block_tag(token, command, parse_until)
  File "/usr/local/python/3.10.13/lib/python3.10/site-packages/django/template/base.py", line 573, in invalid_block_tag
    raise self.error(
django.template.exceptions.TemplateSyntaxError: Invalid block tag on line 3: 'static'. Did you forget to register or load this tag?
ERROR 2024-08-23 12:22:55,267 basehttp 2579 138526756001536 "GET /accounts/login/ HTTP/1.1" 500 150925
ERROR 2024-08-23 13:05:37,885 log 18801 129167997765376 Internal Server Error: /accounts/login/
Traceback (most recent call last):
  File "/usr/local/python/3.10.13/lib/python3.10/site-packages/django/template/base.py", line 510, in parse
    compile_func = self.tags[command]
KeyError: 'static'

During handling of the above exception, another exception occurred:

Traceback (most recent call last):
  File "/usr/local/python/3.10.13/lib/python3.10/site-packages/django/core/handlers/exception.py", line 55, in inner
    response = get_response(request)
  File "/usr/local/python/3.10.13/lib/python3.10/site-packages/django/core/handlers/base.py", line 197, in _get_response
    response = wrapped_callback(request, *callback_args, **callback_kwargs)
  File "/workspaces/HRMS/hrms_project/accounts/views/auth_views.py", line 34, in login_view
    return render(request, 'accounts/login.html')
  File "/usr/local/python/3.10.13/lib/python3.10/site-packages/django/shortcuts.py", line 25, in render
    content = loader.render_to_string(template_name, context, request, using=using)
  File "/usr/local/python/3.10.13/lib/python3.10/site-packages/django/template/loader.py", line 61, in render_to_string
    template = get_template(template_name, using=using)
  File "/usr/local/python/3.10.13/lib/python3.10/site-packages/django/template/loader.py", line 15, in get_template
    return engine.get_template(template_name)
  File "/usr/local/python/3.10.13/lib/python3.10/site-packages/django/template/backends/django.py", line 79, in get_template
    return Template(self.engine.get_template(template_name), self)
  File "/usr/local/python/3.10.13/lib/python3.10/site-packages/django/template/engine.py", line 177, in get_template
    template, origin = self.find_template(template_name)
  File "/usr/local/python/3.10.13/lib/python3.10/site-packages/django/template/engine.py", line 159, in find_template
    template = loader.get_template(name, skip=skip)
  File "/usr/local/python/3.10.13/lib/python3.10/site-packages/django/template/loaders/cached.py", line 57, in get_template
    template = super().get_template(template_name, skip)
  File "/usr/local/python/3.10.13/lib/python3.10/site-packages/django/template/loaders/base.py", line 28, in get_template
    return Template(
  File "/usr/local/python/3.10.13/lib/python3.10/site-packages/django/template/base.py", line 154, in __init__
    self.nodelist = self.compile_nodelist()
  File "/usr/local/python/3.10.13/lib/python3.10/site-packages/django/template/base.py", line 196, in compile_nodelist
    nodelist = parser.parse()
  File "/usr/local/python/3.10.13/lib/python3.10/site-packages/django/template/base.py", line 512, in parse
    self.invalid_block_tag(token, command, parse_until)
  File "/usr/local/python/3.10.13/lib/python3.10/site-packages/django/template/base.py", line 573, in invalid_block_tag
    raise self.error(
django.template.exceptions.TemplateSyntaxError: Invalid block tag on line 7: 'static'. Did you forget to register or load this tag?
ERROR 2024-08-23 13:05:37,888 basehttp 18801 129167997765376 "GET /accounts/login/ HTTP/1.1" 500 153289
ERROR 2024-08-23 16:32:00,980 log 42136 136251772487424 Internal Server Error: /accounts/employees/list/
Traceback (most recent call last):
  File "/usr/local/python/3.10.13/lib/python3.10/site-packages/django/core/handlers/exception.py", line 55, in inner
    response = get_response(request)
  File "/usr/local/python/3.10.13/lib/python3.10/site-packages/django/core/handlers/base.py", line 197, in _get_response
    response = wrapped_callback(request, *callback_args, **callback_kwargs)
  File "/usr/local/python/3.10.13/lib/python3.10/site-packages/django/contrib/auth/decorators.py", line 60, in _view_wrapper
    return view_func(request, *args, **kwargs)
  File "/workspaces/HRMS/hrms_project/accounts/views/employee_views.py", line 11, in list_employees
    return render(request, 'accounts/list_employees.html', {'employees': employees})
  File "/usr/local/python/3.10.13/lib/python3.10/site-packages/django/shortcuts.py", line 25, in render
    content = loader.render_to_string(template_name, context, request, using=using)
  File "/usr/local/python/3.10.13/lib/python3.10/site-packages/django/template/loader.py", line 61, in render_to_string
    template = get_template(template_name, using=using)
  File "/usr/local/python/3.10.13/lib/python3.10/site-packages/django/template/loader.py", line 19, in get_template
    raise TemplateDoesNotExist(template_name, chain=chain)
django.template.exceptions.TemplateDoesNotExist: accounts/list_employees.html
ERROR 2024-08-23 16:32:00,981 basehttp 42136 136251772487424 "GET /accounts/employees/list/ HTTP/1.1" 500 96800
ERROR 2024-08-23 16:32:07,077 log 42136 136252020328192 Internal Server Error: /accounts/leaves/approve/
Traceback (most recent call last):
  File "/usr/local/python/3.10.13/lib/python3.10/site-packages/django/template/backends/django.py", line 107, in render
    return self.template.render(context)
  File "/usr/local/python/3.10.13/lib/python3.10/site-packages/django/template/base.py", line 171, in render
    return self._render(context)
  File "/usr/local/python/3.10.13/lib/python3.10/site-packages/django/template/base.py", line 163, in _render
    return self.nodelist.render(context)
  File "/usr/local/python/3.10.13/lib/python3.10/site-packages/django/template/base.py", line 1008, in render
    return SafeString("".join([node.render_annotated(context) for node in self]))
  File "/usr/local/python/3.10.13/lib/python3.10/site-packages/django/template/base.py", line 1008, in <listcomp>
    return SafeString("".join([node.render_annotated(context) for node in self]))
  File "/usr/local/python/3.10.13/lib/python3.10/site-packages/django/template/base.py", line 969, in render_annotated
    return self.render(context)
  File "/usr/local/python/3.10.13/lib/python3.10/site-packages/django/template/loader_tags.py", line 134, in render
    compiled_parent = self.get_parent(context)
  File "/usr/local/python/3.10.13/lib/python3.10/site-packages/django/template/loader_tags.py", line 131, in get_parent
    return self.find_template(parent, context)
  File "/usr/local/python/3.10.13/lib/python3.10/site-packages/django/template/loader_tags.py", line 109, in find_template
    template, origin = context.template.engine.find_template(
  File "/usr/local/python/3.10.13/lib/python3.10/site-packages/django/template/engine.py", line 163, in find_template
    raise TemplateDoesNotExist(name, tried=tried)
django.template.exceptions.TemplateDoesNotExist: base.html

The above exception was the direct cause of the following exception:

Traceback (most recent call last):
  File "/usr/local/python/3.10.13/lib/python3.10/site-packages/django/core/handlers/exception.py", line 55, in inner
    response = get_response(request)
  File "/usr/local/python/3.10.13/lib/python3.10/site-packages/django/core/handlers/base.py", line 197, in _get_response
    response = wrapped_callback(request, *callback_args, **callback_kwargs)
  File "/usr/local/python/3.10.13/lib/python3.10/site-packages/django/contrib/auth/decorators.py", line 60, in _view_wrapper
    return view_func(request, *args, **kwargs)
  File "/workspaces/HRMS/hrms_project/accounts/views/leave_views.py", line 7, in approve_leaves
    return render(request, 'accounts/approve_leaves.html', {'leave_requests': leave_requests})
  File "/usr/local/python/3.10.13/lib/python3.10/site-packages/django/shortcuts.py", line 25, in render
    content = loader.render_to_string(template_name, context, request, using=using)
  File "/usr/local/python/3.10.13/lib/python3.10/site-packages/django/template/loader.py", line 62, in render_to_string
    return template.render(context, request)
  File "/usr/local/python/3.10.13/lib/python3.10/site-packages/django/template/backends/django.py", line 109, in render
    reraise(exc, self.backend)
  File "/usr/local/python/3.10.13/lib/python3.10/site-packages/django/template/backends/django.py", line 130, in reraise
    raise new from exc
django.template.exceptions.TemplateDoesNotExist: base.html
ERROR 2024-08-23 16:32:07,079 basehttp 42136 136252020328192 "GET /accounts/leaves/approve/ HTTP/1.1" 500 147729
ERROR 2024-08-23 16:32:09,912 log 42136 136252011935488 Internal Server Error: /accounts/leaves/reports/
Traceback (most recent call last):
  File "/usr/local/python/3.10.13/lib/python3.10/site-packages/django/template/backends/django.py", line 107, in render
    return self.template.render(context)
  File "/usr/local/python/3.10.13/lib/python3.10/site-packages/django/template/base.py", line 171, in render
    return self._render(context)
  File "/usr/local/python/3.10.13/lib/python3.10/site-packages/django/template/base.py", line 163, in _render
    return self.nodelist.render(context)
  File "/usr/local/python/3.10.13/lib/python3.10/site-packages/django/template/base.py", line 1008, in render
    return SafeString("".join([node.render_annotated(context) for node in self]))
  File "/usr/local/python/3.10.13/lib/python3.10/site-packages/django/template/base.py", line 1008, in <listcomp>
    return SafeString("".join([node.render_annotated(context) for node in self]))
  File "/usr/local/python/3.10.13/lib/python3.10/site-packages/django/template/base.py", line 969, in render_annotated
    return self.render(context)
  File "/usr/local/python/3.10.13/lib/python3.10/site-packages/django/template/loader_tags.py", line 134, in render
    compiled_parent = self.get_parent(context)
  File "/usr/local/python/3.10.13/lib/python3.10/site-packages/django/template/loader_tags.py", line 131, in get_parent
    return self.find_template(parent, context)
  File "/usr/local/python/3.10.13/lib/python3.10/site-packages/django/template/loader_tags.py", line 109, in find_template
    template, origin = context.template.engine.find_template(
  File "/usr/local/python/3.10.13/lib/python3.10/site-packages/django/template/engine.py", line 163, in find_template
    raise TemplateDoesNotExist(name, tried=tried)
django.template.exceptions.TemplateDoesNotExist: base.html

The above exception was the direct cause of the following exception:

Traceback (most recent call last):
  File "/usr/local/python/3.10.13/lib/python3.10/site-packages/django/core/handlers/exception.py", line 55, in inner
    response = get_response(request)
  File "/usr/local/python/3.10.13/lib/python3.10/site-packages/django/core/handlers/base.py", line 197, in _get_response
    response = wrapped_callback(request, *callback_args, **callback_kwargs)
  File "/usr/local/python/3.10.13/lib/python3.10/site-packages/django/contrib/auth/decorators.py", line 60, in _view_wrapper
    return view_func(request, *args, **kwargs)
  File "/workspaces/HRMS/hrms_project/accounts/views/leave_views.py", line 12, in leave_reports
    return render(request, 'accounts/leave_reports.html', {'reports': reports})
  File "/usr/local/python/3.10.13/lib/python3.10/site-packages/django/shortcuts.py", line 25, in render
    content = loader.render_to_string(template_name, context, request, using=using)
  File "/usr/local/python/3.10.13/lib/python3.10/site-packages/django/template/loader.py", line 62, in render_to_string
    return template.render(context, request)
  File "/usr/local/python/3.10.13/lib/python3.10/site-packages/django/template/backends/django.py", line 109, in render
    reraise(exc, self.backend)
  File "/usr/local/python/3.10.13/lib/python3.10/site-packages/django/template/backends/django.py", line 130, in reraise
    raise new from exc
django.template.exceptions.TemplateDoesNotExist: base.html
ERROR 2024-08-23 16:32:09,914 basehttp 42136 136252011935488 "GET /accounts/leaves/reports/ HTTP/1.1" 500 146257
ERROR 2024-08-23 16:32:12,457 log 42136 136251789272832 Internal Server Error: /accounts/kyc/pending/
Traceback (most recent call last):
  File "/usr/local/python/3.10.13/lib/python3.10/site-packages/django/template/backends/django.py", line 107, in render
    return self.template.render(context)
  File "/usr/local/python/3.10.13/lib/python3.10/site-packages/django/template/base.py", line 171, in render
    return self._render(context)
  File "/usr/local/python/3.10.13/lib/python3.10/site-packages/django/template/base.py", line 163, in _render
    return self.nodelist.render(context)
  File "/usr/local/python/3.10.13/lib/python3.10/site-packages/django/template/base.py", line 1008, in render
    return SafeString("".join([node.render_annotated(context) for node in self]))
  File "/usr/local/python/3.10.13/lib/python3.10/site-packages/django/template/base.py", line 1008, in <listcomp>
    return SafeString("".join([node.render_annotated(context) for node in self]))
  File "/usr/local/python/3.10.13/lib/python3.10/site-packages/django/template/base.py", line 969, in render_annotated
    return self.render(context)
  File "/usr/local/python/3.10.13/lib/python3.10/site-packages/django/template/loader_tags.py", line 134, in render
    compiled_parent = self.get_parent(context)
  File "/usr/local/python/3.10.13/lib/python3.10/site-packages/django/template/loader_tags.py", line 131, in get_parent
    return self.find_template(parent, context)
  File "/usr/local/python/3.10.13/lib/python3.10/site-packages/django/template/loader_tags.py", line 109, in find_template
    template, origin = context.template.engine.find_template(
  File "/usr/local/python/3.10.13/lib/python3.10/site-packages/django/template/engine.py", line 163, in find_template
    raise TemplateDoesNotExist(name, tried=tried)
django.template.exceptions.TemplateDoesNotExist: base.html

The above exception was the direct cause of the following exception:

Traceback (most recent call last):
  File "/usr/local/python/3.10.13/lib/python3.10/site-packages/django/core/handlers/exception.py", line 55, in inner
    response = get_response(request)
  File "/usr/local/python/3.10.13/lib/python3.10/site-packages/django/core/handlers/base.py", line 197, in _get_response
    response = wrapped_callback(request, *callback_args, **callback_kwargs)
  File "/usr/local/python/3.10.13/lib/python3.10/site-packages/django/contrib/auth/decorators.py", line 60, in _view_wrapper
    return view_func(request, *args, **kwargs)
  File "/workspaces/HRMS/hrms_project/accounts/views/kyc_views.py", line 7, in pending_kyc
    return render(request, 'accounts/pending_kyc.html', {'pending_applications': pending_applications})
  File "/usr/local/python/3.10.13/lib/python3.10/site-packages/django/shortcuts.py", line 25, in render
    content = loader.render_to_string(template_name, context, request, using=using)
  File "/usr/local/python/3.10.13/lib/python3.10/site-packages/django/template/loader.py", line 62, in render_to_string
    return template.render(context, request)
  File "/usr/local/python/3.10.13/lib/python3.10/site-packages/django/template/backends/django.py", line 109, in render
    reraise(exc, self.backend)
  File "/usr/local/python/3.10.13/lib/python3.10/site-packages/django/template/backends/django.py", line 130, in reraise
    raise new from exc
django.template.exceptions.TemplateDoesNotExist: base.html
ERROR 2024-08-23 16:32:12,459 basehttp 42136 136251789272832 "GET /accounts/kyc/pending/ HTTP/1.1" 500 147202
ERROR 2024-08-23 16:32:14,705 log 42136 136251772487424 Internal Server Error: /accounts/kyc/reports/
Traceback (most recent call last):
  File "/usr/local/python/3.10.13/lib/python3.10/site-packages/django/template/backends/django.py", line 107, in render
    return self.template.render(context)
  File "/usr/local/python/3.10.13/lib/python3.10/site-packages/django/template/base.py", line 171, in render
    return self._render(context)
  File "/usr/local/python/3.10.13/lib/python3.10/site-packages/django/template/base.py", line 163, in _render
    return self.nodelist.render(context)
  File "/usr/local/python/3.10.13/lib/python3.10/site-packages/django/template/base.py", line 1008, in render
    return SafeString("".join([node.render_annotated(context) for node in self]))
  File "/usr/local/python/3.10.13/lib/python3.10/site-packages/django/template/base.py", line 1008, in <listcomp>
    return SafeString("".join([node.render_annotated(context) for node in self]))
  File "/usr/local/python/3.10.13/lib/python3.10/site-packages/django/template/base.py", line 969, in render_annotated
    return self.render(context)
  File "/usr/local/python/3.10.13/lib/python3.10/site-packages/django/template/loader_tags.py", line 134, in render
    compiled_parent = self.get_parent(context)
  File "/usr/local/python/3.10.13/lib/python3.10/site-packages/django/template/loader_tags.py", line 131, in get_parent
    return self.find_template(parent, context)
  File "/usr/local/python/3.10.13/lib/python3.10/site-packages/django/template/loader_tags.py", line 109, in find_template
    template, origin = context.template.engine.find_template(
  File "/usr/local/python/3.10.13/lib/python3.10/site-packages/django/template/engine.py", line 163, in find_template
    raise TemplateDoesNotExist(name, tried=tried)
django.template.exceptions.TemplateDoesNotExist: base.html

The above exception was the direct cause of the following exception:

Traceback (most recent call last):
  File "/usr/local/python/3.10.13/lib/python3.10/site-packages/django/core/handlers/exception.py", line 55, in inner
    response = get_response(request)
  File "/usr/local/python/3.10.13/lib/python3.10/site-packages/django/core/handlers/base.py", line 197, in _get_response
    response = wrapped_callback(request, *callback_args, **callback_kwargs)
  File "/usr/local/python/3.10.13/lib/python3.10/site-packages/django/contrib/auth/decorators.py", line 60, in _view_wrapper
    return view_func(request, *args, **kwargs)
  File "/workspaces/HRMS/hrms_project/accounts/views/kyc_views.py", line 12, in kyc_reports
    return render(request, 'accounts/kyc_reports.html', {'kyc_report_data': kyc_report_data})
  File "/usr/local/python/3.10.13/lib/python3.10/site-packages/django/shortcuts.py", line 25, in render
    content = loader.render_to_string(template_name, context, request, using=using)
  File "/usr/local/python/3.10.13/lib/python3.10/site-packages/django/template/loader.py", line 62, in render_to_string
    return template.render(context, request)
  File "/usr/local/python/3.10.13/lib/python3.10/site-packages/django/template/backends/django.py", line 109, in render
    reraise(exc, self.backend)
  File "/usr/local/python/3.10.13/lib/python3.10/site-packages/django/template/backends/django.py", line 130, in reraise
    raise new from exc
django.template.exceptions.TemplateDoesNotExist: base.html
ERROR 2024-08-23 16:32:14,707 basehttp 42136 136251772487424 "GET /accounts/kyc/reports/ HTTP/1.1" 500 146322
ERROR 2024-08-23 16:46:12,160 log 47957 125879669724928 Internal Server Error: /accounts/employees/list/
Traceback (most recent call last):
  File "/usr/local/python/3.10.13/lib/python3.10/site-packages/django/core/handlers/exception.py", line 55, in inner
    response = get_response(request)
  File "/usr/local/python/3.10.13/lib/python3.10/site-packages/django/core/handlers/base.py", line 197, in _get_response
    response = wrapped_callback(request, *callback_args, **callback_kwargs)
  File "/usr/local/python/3.10.13/lib/python3.10/site-packages/django/contrib/auth/decorators.py", line 60, in _view_wrapper
    return view_func(request, *args, **kwargs)
  File "/workspaces/HRMS/hrms_project/accounts/views/employee_views.py", line 11, in list_employees
    return render(request, 'accounts/list_employees.html', {'employees': employees})
  File "/usr/local/python/3.10.13/lib/python3.10/site-packages/django/shortcuts.py", line 25, in render
    content = loader.render_to_string(template_name, context, request, using=using)
  File "/usr/local/python/3.10.13/lib/python3.10/site-packages/django/template/loader.py", line 61, in render_to_string
    template = get_template(template_name, using=using)
  File "/usr/local/python/3.10.13/lib/python3.10/site-packages/django/template/loader.py", line 19, in get_template
    raise TemplateDoesNotExist(template_name, chain=chain)
django.template.exceptions.TemplateDoesNotExist: accounts/list_employees.html
ERROR 2024-08-23 16:46:12,165 basehttp 47957 125879669724928 "GET /accounts/employees/list/ HTTP/1.1" 500 96798
ERROR 2024-08-23 16:59:10,691 auth_views 52929 137979892844288 Login error for user raj.arun@tsvglobal.com: Login failed: Invalid login credentials
